Workbook

Sheet 早读
A1: 9月早读统计表（综合按月计在第一列）
A2: 姓名 | B2: 4-8日 | C2: 11-15日 | D2: 18-22日 | E2: 25-27日 | F2: 合计 | G2: 小计
A3: 李亚红 | B3: 4 | C3: 4 | D3: 4 | E3: 3 | F3: =SUM(B3:E3) -> 15 | G3: =SUBTOTAL(9,B3:E3)*6.5 -> 97.5
A4: 赵晓俊 | B4: 4 | C4: 4 | D4: 4 | E4: 3 | F4: =SUM(B4:E4) -> 15 | G4: =SUBTOTAL(9,B4:E4)*6.5 -> 97.5
A5: 曹颖 | B5: 4 | C5: 4 | D5: 4 | E5: 3 | F5: =SUM(B5:E5) -> 15 | G5: =SUBTOTAL(9,B5:E5)*6.5 -> 97.5
A6: 高晓琳 | B6: 2 | C6: 2 | D6: 2 | E6: 3 | F6: =SUM(B6:E6) -> 9 | G6: =SUBTOTAL(9,B6:E6)*6.5 -> 58.5
A7: 解凌云 | B7: 4 | C7: 4 | D7: 4 | E7: 2 | F7: =SUM(B7:E7) -> 14 | G7: =SUBTOTAL(9,B7:E7)*6.5 -> 91
A8: 杨睿 | B8: 4 | C8: 4 | D8: 4 | E8: 2 | F8: =SUM(B8:E8) -> 14 | G8: =SUBTOTAL(9,B8:E8)*6.5 -> 91
A9: 王晓茹 | B9: 4 | C9: 4 | D9: 4 | E9: 2 | F9: =SUM(B9:E9) -> 14 | G9: =SUBTOTAL(9,B9:E9)*6.5 -> 91
A10: 雷艳 | B10: 4 | C10: 4 | D10: 4 | E10: 3 | F10: =SUM(B10:E10) -> 15 | G10: =SUBTOTAL(9,B10:E10)*10 -> 150
A11: 袁萍 | B11: 4 | C11: 4 | D11: 4 | E11: 3 | F11: =SUM(B11:E11) -> 15 | G11: =SUBTOTAL(9,B11:E11)*10 -> 150
A12: 王泽惠 | B12: 4 | C12: 4 | D12: 4 | E12: 3 | F12: =SUM(B12:E12) -> 15 | G12: =SUBTOTAL(9,B12:E12)*10 -> 150
A13: 卢宁祥 | B13: 4 | C13: 4 | D13: 4 | E13: 2 | F13: =SUM(B13:E13) -> 14 | G13: =SUBTOTAL(9,B13:E13)*6.5 -> 91
A14: 池爱彬 | B14: 2 | C14: 2 | D14: 2 | E14: 1 | F14: =SUM(B14:E14) -> 7 | G14: =SUBTOTAL(9,B14:E14)*6.5 -> 45.5
A15: 汪华锋 | B15: 4 | C15: 4 | D15: 4 | E15: 2 | F15: =SUM(B15:E15) -> 14 | G15: =SUBTOTAL(9,B15:E15)*6.5 -> 91
A16: 吕红冰 | B16: 4 | C16: 4 | D16: 4 | E16: 2 | F16: =SUM(B16:E16) -> 14 | G16: =SUBTOTAL(9,B16:E16)*6.5 -> 91
A17: 刘楠 | B17: 4 | C17: 4 | D17: 4 | E17: 2 | F17: =SUM(B17:E17) -> 14 | G17: =SUBTOTAL(9,B17:E17)*6.5 -> 91
A18: 潘晶 | B18: 4 | C18: 4 | D18: 4 | E18: 2 | F18: =SUM(B18:E18) -> 14 | G18: =SUBTOTAL(9,B18:E18)*6.5 -> 91
A19: 张新望 | B19: 4 | C19: 4 | D19: 4 | E19: 3 | F19: =SUM(B19:E19) -> 15 | G19: =SUBTOTAL(9,B19:E19)*10 -> 150
A20: 方垚 | B20: 4 | C20: 4 | D20: 4 | E20: 3 | F20: =SUM(B20:E20) -> 15 | G20: =SUBTOTAL(9,B20:E20)*10 -> 150
A21: 贾静 | B21: 4 | C21: 4 | D21: 4 | E21: 3 | F21: =SUM(B21:E21) -> 15 | G21: =SUBTOTAL(9,B21:E21)*10 -> 150
A22: 山欢 | B22: 2 | F22: =SUM(B22:E22) -> 2 | G22: =SUBTOTAL(9,B22:E22)*6.5 -> 13
A23: 李丛丛 | B23: 0 | F23: =SUM(B23:E23) -> 0 | G23: =SUBTOTAL(9,B23:E23)*6.5 -> 0
A24: 付冲 | B24: 2 | F24: =SUM(B24:E24) -> 2 | G24: =SUBTOTAL(9,B24:E24)*6.5 -> 13
A25: 王波波 | B25: 2 | C25: 1 | F25: =SUM(B25:E25) -> 3 | G25: =SUBTOTAL(9,B25:E25)*6.5 -> 19.5
A26: 段洁 | B26: 2 | C26: 1 | F26: =SUM(B26:E26) -> 3 | G26: =SUBTOTAL(9,B26:E26)*6.5 -> 19.5
A27: 赵娟 | B27: 2 | F27: =SUM(B27:E27) -> 2 | G27: =SUBTOTAL(9,B27:E27)*10 -> 20
A28: 刘青 | B28: 1 | F28: =SUM(B28:E28) -> 1 | G28: =SUBTOTAL(9,B28:E28)*10 -> 10
A29: 张秀利 | F29: =SUM(B29:E29) -> 0 | G29: =SUBTOTAL(9,B29:E29)*10 -> 0
A30: 赵雅 | B30: 3 | F30: =SUM(B30:E30) -> 3 | G30: =SUBTOTAL(9,B30:E30)*6.5 -> 19.5
A31: 陶媛 | B31: 2 | F31: =SUM(B31:E31) -> 2 | G31: =SUBTOTAL(9,B31:E31)*6.5 -> 13
A32: 金婷 | B32: 2 | F32: =SUM(B32:E32) -> 2 | G32: =SUBTOTAL(9,B32:E32)*6.5 -> 13
A33: 魏军超 | B33: 2 | F33: =SUM(B33:E33) -> 2 | G33: =SUBTOTAL(9,B33:E33)*6.5 -> 13
A34: 张荣娟 | B34: 2 | F34: =SUM(B34:E34) -> 2 | G34: =SUBTOTAL(9,B34:E34)*10 -> 20
A35: 张长青 | F35: =SUM(B35:E35) -> 0 | G35: =SUBTOTAL(9,B35:E35)*6.5 -> 0
A36: 韦东 | B36: 4 | F36: =SUM(B36:E36) -> 4 | G36: =SUBTOTAL(9,B36:E36)*6.5 -> 26
A37: 姜小鹏 | B37: 2 | C37: 1 | F37: =SUM(B37:E37) -> 3 | G37: =SUBTOTAL(9,B37:E37)*6.5 -> 19.5
A38: 肖雅静 | B38: 2 | F38: =SUM(B38:E38) -> 2 | G38: =SUBTOTAL(9,B38:E38)*10 -> 20
A39: 毕文娟 | B39: 4 | F39: =SUM(B39:E39) -> 4 | G39: =SUBTOTAL(9,B39:E39)*6.5 -> 26
A40: 刘一依 | B40: 2 | C40: 1 | F40: =SUM(B40:E40) -> 3 | G40: =SUBTOTAL(9,B40:E40)*6.5 -> 19.5
...

Sheet Sheet3
A1: 姓名 | B1: 早读
A2: 虎云兵
A3: 李少波
A4: 秋军辉
A5: 曹峰 | B5: =VLOOKUP(A5,Sheet1!$A$1:$B$70,2,FALSE) -> 0
A6: 李纯福
A7: 王艳 | B7: =VLOOKUP(A7,Sheet1!$A$1:$B$70,2,FALSE) -> 0
A8: 王峰
A9: 肖有福
A10: 吴红莲 | B10: =VLOOKUP(A10,Sheet1!$A$1:$B$70,2,FALSE) -> 19.5
A11: 薛国庆
A12: 李琼 | B12: =VLOOKUP(A12,Sheet1!$A$1:$B$70,2,FALSE) -> 0
A13: 雷军平
A14: 张瑶
A15: 尚小明
A16: 阎秦安
A17: 白峰
A18: 梁建
A19: 雷艳 | B19: =VLOOKUP(A19,Sheet1!$A$1:$B$70,2,FALSE) -> 10
A20: 李亚红 | B20: =VLOOKUP(A20,Sheet1!$A$1:$B$70,2,FALSE) -> 10
A21: 赵晓俊 | B21: =VLOOKUP(A21,Sheet1!$A$1:$B$70,2,FALSE) -> 10
A22: 高晓琳 | B22: =VLOOKUP(A22,Sheet1!$A$1:$B$70,2,FALSE) -> 45.5
A23: 袁萍 | B23: =VLOOKUP(A23,Sheet1!$A$1:$B$70,2,FALSE) -> 84.5
A24: 王泽惠 | B24: =VLOOKUP(A24,Sheet1!$A$1:$B$70,2,FALSE) -> 84.5
A25: 杨睿 | B25: =VLOOKUP(A25,Sheet1!$A$1:$B$70,2,FALSE) -> 110.5
A26: 王晓茹 | B26: =VLOOKUP(A26,Sheet1!$A$1:$B$70,2,FALSE) -> 97.5
A27: 解凌云 | B27: =VLOOKUP(A27,Sheet1!$A$1:$B$70,2,FALSE) -> 97.5
A28: 朱亚军
A29: 梁笛
A30: 刘梦花 | B30: =VLOOKUP(A30,Sheet1!$A$1:$B$70,2,FALSE) -> 6.5
A31: 刘亚飞
A32: 贾丹琴
A33: 张小鸽 | B33: =VLOOKUP(A33,Sheet1!$A$1:$B$70,2,FALSE) -> 13
A34: 杨杰
A35: 吴花茹
A36: 宋娟宁
A37: 李粉婷
A38: 卢宁祥 | B38: =VLOOKUP(A38,Sheet1!$A$1:$B$70,2,FALSE) -> 10
A39: 池爱彬 | B39: =VLOOKUP(A39,Sheet1!$A$1:$B$70,2,FALSE) -> 10
A40: 方垚 | B40: =VLOOKUP(A40,Sheet1!$A$1:$B$70,2,FALSE) -> 10
...

Sheet Sheet1
A1: 姓名 | B1: 早读
A2: 曹峰 | B2: 0
A3: 雷艳 | B3: 10
A4: 李亚红 | B4: 10
A5: 赵晓俊 | B5: 10
A6: 高晓琳 | B6: 45.5
A7: 袁萍 | B7: 84.5
A8: 王泽惠 | B8: 84.5
A9: 杨睿 | B9: 110.5
A10: 王晓茹 | B10: 97.5
A11: 解凌云 | B11: 97.5
A12: 卢宁祥 | B12: 10
A13: 池爱彬 | B13: 10
... A70: 刘梦花 | B70: 6.5

Sheet Sheet2
A1: A | B1: 政治 马盼盼 | C1: 地理 屈锦博 | D1: 生物 肖雅静 | E1: 物理 赵娟 | F1: 化学 张荣娟 | G1: 物理 李丛丛 | H1: 物理 吴红莲
A2: B | B2: 地理 屈锦博 | C2: 历史 刘艳纯 | D2: 化学 周阿红 | E2: 生物 肖雅静 | F2: 物理 李丛丛 | G2: 生物 田佳 | H2: 化学 张荣娟
A3: C | B3: 历史 刘艳纯 | C3: 政治 马盼盼 | D3: 物理 赵娟 | E3: 化学 周阿红 | F3: 生物 田佳 | G3: 化学 张荣娟 | H3: 生物 肖雅静
A5: 周一综合早读安排（7:40--8:00）
B6: 1班 | C6: 2班 | D6: 3班 | E6: 4班 | F6: 5班 | G6: 6班 | H6: 7班
A7: A | B7: 政治 马盼盼 | C7: 地理 屈锦博 | D7: 生物 肖雅静 | E7: 物理 赵娟 | F7: 化学 张荣娟 | G7: 物理 李丛丛 | H7: 物理 吴红莲
A10: 冯宏强 | B10: 王铭 | C10: 张秀丽 | D10: 韦东 | E10: 陶媛 | F10: 刘青 | G10: 付冲
A11: 王铭 | B11: 毕文娟 | C11: 韦东 | D11: 陶媛 | E11: 刘青 | F11: 代斌 | G11: 赵雅
A12: 毕文娟 | B12: 冯宏强 | C12: 赵雅 | D12: 付冲 | E12: 韦东 | F12: 陶媛 | G12: 代斌
A13: 冯宏强 | B13: 王铭 | C13: 张秀丽 | D13: 韦东 | E13: 陶媛 | F13: 刘青 | G13: 付冲

Sheet Sheet2 (3)
A1: 综合早读统计表
A3: 曹峰 | B3: 2 | C3: 2 | D3: 0 | E3: 2
A4: 雷艳 | B4: 4 | C4: 4 | D4: 4 | E4: 4
A5: 李亚红 | B5: 4 | C5: 4 | D5: 4 | E5: 4
A6: 赵晓俊 | B6: 4 | C6: 4 | D6: 4 | E6: 4
A7: 高晓琳 | B7: 1 | C7: 2 | D7: 2 | E7: 2
A8: 袁萍 | B8: 2 | C8: 4 | D8: 4 | E8: 4
A9: 王泽惠 | B9: 2 | C9: 4 | D9: 4 | E9: 4
A10: 杨睿 | B10: 1 | C10: 4 | D10: 4 | E10: 4
A11: 王晓茹 | B11: 1 | C11: 4 | D11: 4 | E11: 4
A12: 解凌云 | B12: 1 | C12: 4 | D12: 4 | E12: 4
A13: 卢宁祥 | B13: 4 | C13: 4 | D13: 4 | E13: 4
A14: 池爱彬 | B14: 2 | C14: 2 | D14: 2 | E14: 2
... A20: 吕红冰 | B20: 2 | C20: 4 | D20: 4 | E20: 4
A21: 张秀利
A22: 刘青
A23: 付冲
A24: 赵娟
A25: 李丛丛
A26: 王波波
A27: 段洁
A28: 陶媛
A29: 赵雅
A30: 张长青
A31: 张荣娟
A32: 魏军超
... A54: 代斌
